 * Serving Flask app 'app'
 * Debug mode: on
[31m[1mWARNING: This is a development server. Do not use it in a production deployment. Use a production WSGI server instead.[0m
 * Running on all addresses (0.0.0.0)
 * Running on http://127.0.0.1:5003
 * Running on http://192.168.47.128:5003
[33mPress CTRL+C to quit[0m
 * Restarting with stat
 * Debugger is active!
 * Debugger PIN: 156-800-191
192.168.47.1 - - [28/Jan/2025 17:44:50] "GET / HTTP/1.1" 200 -
192.168.47.1 - - [28/Jan/2025 17:44:59] "[32mPOST /capture HTTP/1.1[0m" 302 -
192.168.47.1 - - [28/Jan/2025 17:45:01] "GET /view_capture?capture_file=capture_eth0.pcap HTTP/1.1" 200 -
192.168.47.1 - - [28/Jan/2025 17:45:44] "GET / HTTP/1.1" 200 -
Exception ignored in: <function BaseSubprocessTransport.__del__ at 0x7f97bca36020>
Traceback (most recent call last):
  File "/usr/lib/python3.12/asyncio/base_subprocess.py", line 126, in __del__
    self.close()
  File "/usr/lib/python3.12/asyncio/base_subprocess.py", line 104, in close
    proto.pipe.close()
  File "/usr/lib/python3.12/asyncio/unix_events.py", line 568, in close
    self._close(None)
  File "/usr/lib/python3.12/asyncio/unix_events.py", line 592, in _close
    self._loop.call_soon(self._call_connection_lost, exc)
  File "/usr/lib/python3.12/asyncio/base_events.py", line 794, in call_soon
    self._check_closed()
  File "/usr/lib/python3.12/asyncio/base_events.py", line 540, in _check_closed
    raise RuntimeError('Event loop is closed')
RuntimeError: Event loop is closed
192.168.47.1 - - [28/Jan/2025 17:45:50] "[32mPOST /capture HTTP/1.1[0m" 302 -
192.168.47.1 - - [28/Jan/2025 17:45:51] "GET /view_capture?capture_file=capture_eth0.pcap HTTP/1.1" 200 -
192.168.47.1 - - [28/Jan/2025 17:46:11] "GET / HTTP/1.1" 200 -
Exception ignored in: <function BaseSubprocessTransport.__del__ at 0x7f97bca36020>
Traceback (most recent call last):
  File "/usr/lib/python3.12/asyncio/base_subprocess.py", line 126, in __del__
    self.close()
  File "/usr/lib/python3.12/asyncio/base_subprocess.py", line 104, in close
    proto.pipe.close()
  File "/usr/lib/python3.12/asyncio/unix_events.py", line 568, in close
    self._close(None)
  File "/usr/lib/python3.12/asyncio/unix_events.py", line 592, in _close
    self._loop.call_soon(self._call_connection_lost, exc)
  File "/usr/lib/python3.12/asyncio/base_events.py", line 794, in call_soon
    self._check_closed()
  File "/usr/lib/python3.12/asyncio/base_events.py", line 540, in _check_closed
    raise RuntimeError('Event loop is closed')
RuntimeError: Event loop is closed
192.168.47.1 - - [28/Jan/2025 17:46:25] "[32mPOST /capture HTTP/1.1[0m" 302 -
192.168.47.1 - - [28/Jan/2025 17:46:26] "GET /view_capture?capture_file=capture_eth0.pcap HTTP/1.1" 200 -
192.168.47.1 - - [28/Jan/2025 17:50:10] "GET / HTTP/1.1" 200 -
192.168.47.128 - - [28/Jan/2025 17:50:26] "GET / HTTP/1.1" 200 -
Exception ignored in: <function BaseSubprocessTransport.__del__ at 0x7f97bca36020>
Traceback (most recent call last):
  File "/usr/lib/python3.12/asyncio/base_subprocess.py", line 126, in __del__
    self.close()
  File "/usr/lib/python3.12/asyncio/base_subprocess.py", line 104, in close
    proto.pipe.close()
  File "/usr/lib/python3.12/asyncio/unix_events.py", line 568, in close
    self._close(None)
  File "/usr/lib/python3.12/asyncio/unix_events.py", line 592, in _close
    self._loop.call_soon(self._call_connection_lost, exc)
  File "/usr/lib/python3.12/asyncio/base_events.py", line 794, in call_soon
    self._check_closed()
  File "/usr/lib/python3.12/asyncio/base_events.py", line 540, in _check_closed
    raise RuntimeError('Event loop is closed')
RuntimeError: Event loop is closed
